<mujoco model="DUALARM.SLDASM">
  <compiler angle="radian" meshdir="meshes/"/>
  <option integrator="implicitfast"/>
  <asset>
    <mesh name="base_link" file="base_link.STL"/>
    <mesh name="L1" file="L1.STL"/>
    <mesh name="L2" file="L2.STL"/>
    <mesh name="L3" file="L3.STL"/>
    <mesh name="L4" file="L4.STL"/>
    <mesh name="L5" file="L5.STL"/>
    <mesh name="L6" file="L6.STL"/>
    <mesh name="L7" file="L7.STL"/>
    <mesh name="L8" file="L8.STL"/>
    <mesh name="L9" file="L9.STL"/>
    <mesh name="L10" file="L10.STL"/>
    <mesh name="L11" file="L11.STL"/>
    <mesh name="L12" file="L12.STL"/>
    <mesh name="L13" file="L13.STL"/>
    <mesh name="L14" file="L14.STL"/>
  </asset>

  <default>
    <default class="RAW">
      <joint range="-3.14 3.14"/>
      <general ctrlrange="-3.14 3.14" gaintype="fixed" biastype="affine" gainprm="2000" biasprm="0 -2000 -200"/>
    </default>
    <default class="PITCH_big">
      <joint range="-1.4835299 1.4835299"/>
      <general ctrlrange="-1.4835299 1.4835299" gaintype="fixed" biastype="affine" gainprm="2000" biasprm="0 -2000 -200"/>
    </default>
    <default class="PITCH">
      <joint range="-1.3089969 1.3089969"/>
      <general ctrlrange="-1.3089969 1.3089969" gaintype="fixed" biastype="affine" gainprm="2000" biasprm="0 -2000 -200"/>
    </default>
  </default>

  <worldbody>
    <geom type="mesh" contype="0" conaffinity="0" group="1" density="0" rgba="0.792157 0.819608 0.933333 1" mesh="base_link"/>
<!--    <geom type="mesh" rgba="0.792157 0.819608 0.933333 1" mesh="base_link"/>-->
    <body name="L1" pos="0 0.14331 0.33244" quat="0.8660254 -0.50000 0 0">
      <inertial pos="-2.54816e-07 0.000220683 0.0591882" quat="0.704538 0.0600183 -0.0598814 0.704584" mass="0.256101" diaginertia="0.000520388 0.000503496 0.000461003"/>
      <joint name="J1" pos="0 0 0" axis="0 0 1" class="RAW"/>
      <geom type="mesh" contype="0" conaffinity="0" group="1" density="0" rgba="0.792157 0.819608 0.933333 1" mesh="L1"/>
      <geom type="mesh" rgba="0.792157 0.819608 0.933333 1" mesh="L1"/>
      <body name="L2" pos="0 0 0.085" quat="0.707105 -0.707108 0 0">
        <inertial pos="-6.15475e-05 -0.0254038 -0.00770433" quat="0.998651 0.0518821 -0.00028413 -0.00212822" mass="0.203365" diaginertia="0.000711807 0.000636282 0.000347615"/>
        <joint name="J2" pos="0 0 0" axis="0 0 1" class="PITCH_big"/>
        <geom type="mesh" contype="0" conaffinity="0" group="1" density="0" rgba="0.792157 0.819608 0.933333 1" mesh="L2"/>
        <geom type="mesh" rgba="0.792157 0.819608 0.933333 1" mesh="L2"/>
        <body name="L3" pos="0 -0.0665 0" quat="0.707105 0.707108 0 0">
          <inertial pos="3.43687e-05 -0.00171785 0.090774" quat="0.998451 0.0556063 0.000275665 -0.00163807" mass="0.594887" diaginertia="0.00136272 0.00116006 0.000824936"/>
          <joint name="J3" pos="0 0 0" axis="0 0 1" class="RAW"/>
          <geom type="mesh" contype="0" conaffinity="0" group="1" density="0" rgba="0.792157 0.819608 0.933333 1" mesh="L3"/>
          <geom type="mesh" rgba="0.792157 0.819608 0.933333 1" mesh="L3"/>
          <body name="L4" pos="0 0 0.1835" quat="0.499998 0.5 -0.5 0.500002">
            <inertial pos="0.012252 5.60753e-06 0.00299782" quat="-0.000191729 0.686583 -9.14932e-05 0.727051" mass="0.162422" diaginertia="0.000322962 0.000311279 0.000245846"/>
            <joint name="J4" pos="0 0 0" axis="0 0 -1" class="PITCH"/>
            <geom type="mesh" contype="0" conaffinity="0" group="1" density="0" rgba="0.792157 0.819608 0.933333 1" mesh="L4"/>
            <geom type="mesh" rgba="0.792157 0.819608 0.933333 1" mesh="L4"/>
            <body name="L5" pos="0.0605 0 0" quat="0.499998 0.5 0.500002 0.5">
              <inertial pos="1.81608e-06 -0.00153728 0.0816001" quat="0.997061 0.0766126 -6.46332e-05 3.30323e-05" mass="0.144842" diaginertia="0.000301099 0.000237452 0.000161152"/>
              <joint name="J5" pos="0 0 0" axis="0 0 1" class="RAW"/>
              <geom type="mesh" contype="0" conaffinity="0" group="1" density="0" rgba="0.792157 0.819608 0.933333 1" mesh="L5"/>
              <geom type="mesh" rgba="0.792157 0.819608 0.933333 1" mesh="L5"/>
              <body name="L6" pos="0 0 0.1495" quat="0.707105 -0.707108 0 0">
                <inertial pos="-0.00340681 -0.030349 -0.00101337" quat="0.520426 0.367659 -0.533336 0.55636" mass="0.0922109" diaginertia="0.000167493 0.000165763 0.000100994"/>
                <joint name="J6" pos="0 0 0" axis="0 0 -1" class="PITCH"/>
                <geom type="mesh" contype="0" conaffinity="0" group="1" density="0" rgba="0.792157 0.819608 0.933333 1" mesh="L6"/>
                <geom type="mesh" rgba="0.792157 0.819608 0.933333 1" mesh="L6"/>
                <body name="L7" pos="0 -0.062 0" quat="0.499998 -0.5 0.500002 -0.5">
                  <inertial pos="0.0153453 9.27391e-06 1.34171e-05" quat="0.71 0.013705 0.0138066 0.703933" mass="0.059033" diaginertia="9.54069e-05 9.25805e-05 3.54181e-05"/>
                  <joint name="J7" pos="0 0 0" axis="0 0 1" class="RAW"/>
                  <geom type="mesh" contype="0" conaffinity="0" group="1" density="0" rgba="0.792157 0.819608 0.933333 1" mesh="L7"/>
                  <geom type="mesh" rgba="0.792157 0.819608 0.933333 1" mesh="L7"/>
                  <site name="end_effector_right" pos="0.05 0.0 0" quat="0.7071068 0 0.7071068 0"/>
                </body>
              </body>
            </body>
          </body>
        </body>
      </body>
    </body>
    <body name="L8" pos="0 -0.14331 0.33244" quat="0.866025 0.500001 0 0">
      <inertial pos="2.55277e-07 -0.000220685 0.0581882" quat="0.704537 -0.0600183 0.0598815 0.704585" mass="0.256101" diaginertia="0.000520388 0.000503496 0.000461003"/>
      <joint name="J8" pos="0 0 0" axis="0 0 -1" class="RAW"/>
      <geom type="mesh" contype="0" conaffinity="0" group="1" density="0" rgba="0.792157 0.819608 0.933333 1" mesh="L8"/>
      <geom type="mesh" rgba="0.792157 0.819608 0.933333 1" mesh="L8"/>
      <body name="L9" pos="0 0 0.085" quat="0.707105 0.707108 0 0">
        <inertial pos="6.15475e-05 0.0244038 -0.00770433" quat="0.998651 -0.0518821 0.00028413 -0.00212822" mass="0.203365" diaginertia="0.000711807 0.000636282 0.000347615"/>
        <joint name="J9" pos="0 0 0" axis="0 0 -1" class="PITCH_big"/>
        <geom type="mesh" contype="0" conaffinity="0" group="1" density="0" rgba="0.792157 0.819608 0.933333 1" mesh="L9"/>
        <geom type="mesh" rgba="0.792157 0.819608 0.933333 1" mesh="L9"/>
        <body name="L10" pos="0 0.0665 0" quat="0.707105 -0.707108 0 0">
          <inertial pos="-3.43687e-05 0.00171785 0.089774" quat="0.998451 -0.0556063 -0.000275665 -0.00163807" mass="0.594887" diaginertia="0.00136272 0.00116006 0.000824936"/>
          <joint name="J10" pos="0 0 0" axis="0 0 -1" class="RAW"/>
          <geom type="mesh" contype="0" conaffinity="0" group="1" density="0" rgba="0.792157 0.819608 0.933333 1" mesh="L10"/>
          <geom type="mesh" rgba="0.792157 0.819608 0.933333 1" mesh="L10"/>
          <body name="L11" pos="0 0 0.1835" quat="0.707105 0.707108 0 0">
            <inertial pos="-5.60753e-06 0.011252 0.00299782" quat="0.485553 0.514238 -0.513967 0.485423" mass="0.162422" diaginertia="0.000322962 0.000311279 0.000245846"/>
            <joint name="J11" pos="0 0 0" axis="0 0 -1" class="PITCH"/>
            <geom type="mesh" contype="0" conaffinity="0" group="1" density="0" rgba="0.792157 0.819608 0.933333 1" mesh="L11"/>
            <geom type="mesh" rgba="0.792157 0.819608 0.933333 1" mesh="L11"/>
            <body name="L12" pos="0 0.0605 0" quat="0.707105 -0.707108 0 0">
              <inertial pos="-1.81608e-06 0.00153728 0.0806001" quat="0.997061 -0.0766126 6.46332e-05 3.30323e-05" mass="0.144842" diaginertia="0.000301099 0.000237452 0.000161152"/>
              <joint name="J12" pos="0 0 0" axis="0 0 -1" class="RAW"/>
              <geom type="mesh" contype="0" conaffinity="0" group="1" density="0" rgba="0.792157 0.819608 0.933333 1" mesh="L12"/>
              <geom type="mesh" rgba="0.792157 0.819608 0.933333 1" mesh="L12"/>
              <body name="L13" pos="0 0 0.1495" quat="0.707105 0.707108 0 0">
                <inertial pos="0.00340681 0.029349 -0.00101337" quat="0.533336 0.556361 -0.520426 0.367657" mass="0.0922109" diaginertia="0.000167492 0.000165763 0.000100994"/>
                <joint name="J13" pos="0 0 0" axis="0 0 -1" class="PITCH"/>
                <geom type="mesh" contype="0" conaffinity="0" group="1" density="0" rgba="0.792157 0.819608 0.933333 1" mesh="L13"/>
                <geom type="mesh" rgba="0.792157 0.819608 0.933333 1" mesh="L13"/>
                <body name="L14" pos="0 0.062 0" quat="0.499998 0.5 0.500002 0.5">
                  <inertial pos="0.0143453 -9.27391e-06 -1.34171e-05" quat="0.703933 -0.0138066 -0.013705 0.71" mass="0.059033" diaginertia="9.54069e-05 9.25805e-05 3.54181e-05"/>
                  <joint name="J14" pos="0 0 0" axis="0 0 1" class="RAW"/>
                  <geom type="mesh" contype="0" conaffinity="0" group="1" density="0" rgba="0.792157 0.819608 0.933333 1" mesh="L14"/>
                  <geom type="mesh" rgba="0.792157 0.819608 0.933333 1" mesh="L14"/>
                  <site name="end_effector_left" pos="0.05 0.0 0" quat="0.7071068 0 0.7071068 0"/>
                </body>
              </body>
            </body>
          </body>
        </body>
      </body>
    </body>
  </worldbody>

  <actuator>
    <general name="actuator1" joint="J1" class = "RAW"/>
    <general name="actuator2" joint="J2" class = "PITCH_big"/>
    <general name="actuator3" joint="J3" class = "RAW"/>
    <general name="actuator4" joint="J4" class = "PITCH"/>
    <general name="actuator5" joint="J5" class = "RAW"/>
    <general name="actuator6" joint="J6" class = "PITCH"/>
    <general name="actuator7" joint="J7" class = "RAW"/>
    <general name="actuator8" joint="J8" class = "RAW"/>
    <general name="actuator9" joint="J9" class = "PITCH_big"/>
    <general name="actuator10" joint="J10" class = "RAW"/>
    <general name="actuator11" joint="J11" class = "PITCH"/>
    <general name="actuator12" joint="J12" class = "RAW"/>
    <general name="actuator13" joint="J13" class = "PITCH"/>
    <general name="actuator14" joint="J14" class = "RAW"/>
  </actuator>

  <keyframe>
    <key name="home" qpos="0 0 0 0 0 0 0 0 0 0 0 0 0 0" ctrl = "0 0 0 0 0 0 0 0 0 0 0 0 0 0"/>
    <key name="pos1" qpos="0.69 1.05 0.0786 1.05 0 0 0 0.69 1.05 0.0786 1.05 0 0 0 " ctrl = "0.69 1.05 0.0786 1.25 0 0 0 0.69 1.05 0.0786 1.05 0 0 0 "/>
    <key name="pos2" qpos="0.0943 0.742 0.581 1.05 0.581 0.654 0.0 0.345 0.525 0.0393 0.525 0.581 0.654 0.0" ctrl = "0.0943 0.742 0.581 1.05 0.581 0.654 0.0 0.345 0.525 0.0393 0.525 0.581 0.654 0.0"/>
    <key name="pos3" qpos="0.1725 0.2625 0.01965 0.2625 0 0 0 0.1725 0.2625 0.01965 0.2625 0 0 0" ctrl = "0.1725 0.2625 0.01965 0.2625 0 0 0 0.1725 0.2625 0.01965 0.2625 0 0 0"/>
    <key name="pos4" qpos="0.0 0.3 0 0.3 0 0 0 0.0 0.3 0 0.3 0 0 0" ctrl = "0.0 0.3 0 0.3 0 0 0 0.0 0.3 0 0.3 0 0 0"/>
  </keyframe>
</mujoco>

